- `panic` 能够改变程序的控制流，调用 `panic` 后会立刻停止执行当前函数的剩余代码，并在当前 Goroutine 中递归执行调用方的 `defer`；
- `recover` 可以中止 `panic` 造成的程序崩溃。它是一个只能在 `defer` 中发挥作用的函数，在其他作用域中调用不会发挥作用；

#### 跨协程失效

```go
func main() {
	defer println("in main")
	go func() {
		defer println("in goroutine")
		panic("")
	}()

	time.Sleep(1 * time.Second)
}
```

当我们运行这段代码时会发现 `main` 函数中的 `defer` 语句并没有执行，执行的只有当前 Goroutine 中的 `defer`。

`defer` 关键字对应的 `runtime.deferproc`会将延迟调用函数与调用方所在 Goroutine 进行关联。所以当程序发生崩溃时只会调用当前 Goroutine 的延迟调用函数也是非常合理的。

![golang-panic-and-defers](https://img.draveness.me/2020-01-19-15794253176199-golang-panic-and-defers.png)

如上图所示，多个 Goroutine 之间没有太多的关联，一个 Goroutine 在 `panic` 时也不应该执行其他 Goroutine 的延迟函数。

#### 嵌套崩溃

Go 语言中的 `panic` 是可以多次嵌套调用的。一些熟悉 Go 语言的读者很可能也不知道这个知识点，如下所示的代码就展示了如何在 `defer` 函数中多次调用 `panic`：

```go
func main() {
	defer fmt.Println("in main")
	defer func() {
		defer func() {
			panic("panic again and again")
		}()
		panic("panic again")
	}()

	panic("panic once")
}

$ go run main.go
in main
panic: panic once
	panic: panic again
	panic: panic again and again

goroutine 1 [running]:
...
exit status 2
```

从上述程序输出的结果，我们可以确定程序多次调用 `panic` 也不会影响 `defer` 函数的正常执行，所以使用 `defer` 进行收尾工作一般来说都是安全的。